28821
train indices: 23056
subset: 23056
Training started:
Epoch 1 Started
validation started
validation total 5765
Epoch 1 Ended and logged in wandb
Epoch 2 Started
validation started
validation total 5765
Epoch 2 Ended and logged in wandb
Epoch 3 Started
validation started
validation total 5765
Epoch 3 Ended and logged in wandb
Epoch 4 Started
validation started
validation total 5765
Epoch 4 Ended and logged in wandb
Epoch 5 Started
validation started
validation total 5765
Epoch 5 Ended and logged in wandb
Epoch 6 Started
validation started
validation total 5765
Epoch 6 Ended and logged in wandb
Epoch 7 Started
Exception ignored in: <function _releaseLock at 0x1484ebb6aca0>
Traceback (most recent call last):
  File "/afs/crc.nd.edu/user/p/psharma3/.conda/envs/NNproject/lib/python3.11/logging/__init__.py", line 237, in _releaseLock
    def _releaseLock():
KeyboardInterrupt:
validation started
Traceback (most recent call last):
  File "/afs/crc.nd.edu/user/p/psharma3/.conda/envs/NNproject/lib/python3.11/site-packages/torch/utils/data/dataloader.py", line 1133, in _try_get_data
    data = self._data_queue.get(timeout=timeout)
           ^^^^^^^^^^^^^^^^^^^^^^^^^^^^^^^^^^^^^
  File "/afs/crc.nd.edu/user/p/psharma3/.conda/envs/NNproject/lib/python3.11/multiprocessing/queues.py", line 114, in get
    raise Empty
_queue.Empty
The above exception was the direct cause of the following exception:
Traceback (most recent call last):
  File "/afs/crc.nd.edu/user/p/psharma3/NNproject/models/main.py", line 127, in <module>
    for val_data,val_labels in val_loader:
  File "/afs/crc.nd.edu/user/p/psharma3/.conda/envs/NNproject/lib/python3.11/site-packages/torch/utils/data/dataloader.py", line 634, in __next__
    data = self._next_data()
           ^^^^^^^^^^^^^^^^^
  File "/afs/crc.nd.edu/user/p/psharma3/.conda/envs/NNproject/lib/python3.11/site-packages/torch/utils/data/dataloader.py", line 1329, in _next_data
    idx, data = self._get_data()
                ^^^^^^^^^^^^^^^^
  File "/afs/crc.nd.edu/user/p/psharma3/.conda/envs/NNproject/lib/python3.11/site-packages/torch/utils/data/dataloader.py", line 1295, in _get_data
    success, data = self._try_get_data()
                    ^^^^^^^^^^^^^^^^^^^^
  File "/afs/crc.nd.edu/user/p/psharma3/.conda/envs/NNproject/lib/python3.11/site-packages/torch/utils/data/dataloader.py", line 1146, in _try_get_data
    raise RuntimeError('DataLoader worker (pid(s) {}) exited unexpectedly'.format(pids_str)) from e
RuntimeError: DataLoader worker (pid(s) 382353) exited unexpectedly